Input Notebook:  validator2.ipynb
Output Notebook: output.ipynb
Executing:   0%|          | 0/14 [00:00<?, ?cell/s]Executing notebook with kernel: python3
Executing:   7%|▋         | 1/14 [00:00<00:08,  1.51cell/s]Executing:  14%|█▍        | 2/14 [00:00<00:04,  2.50cell/s]Executing:  64%|██████▍   | 9/14 [00:00<00:00, 13.91cell/s]--2023-01-04 06:02:02--  http://tb.plazi.org/GgServer/dwca/FFF07216FFA41642FFBAFFE7FFCA482A.zip
Resolving tb.plazi.org (tb.plazi.org)... failed: Name or service not known.
wget: unable to resolve host address ‘tb.plazi.org’
Executing:  93%|█████████▎| 13/14 [00:01<00:00, 18.60cell/s]Executing: 100%|██████████| 14/14 [00:01<00:00,  9.84cell/s]
Traceback (most recent call last):
  File "/home/aubrey/.local/bin/papermill", line 8, in <module>
    sys.exit(papermill())
  File "/home/aubrey/.local/lib/python3.8/site-packages/click/core.py", line 1137, in __call__
    return self.main(*args, **kwargs)
  File "/home/aubrey/.local/lib/python3.8/site-packages/click/core.py", line 1062, in main
    rv = self.invoke(ctx)
  File "/home/aubrey/.local/lib/python3.8/site-packages/click/core.py", line 1404, in invoke
    return ctx.invoke(self.callback, **ctx.params)
  File "/home/aubrey/.local/lib/python3.8/site-packages/click/core.py", line 763, in invoke
    return __callback(*args, **kwargs)
  File "/home/aubrey/.local/lib/python3.8/site-packages/click/decorators.py", line 26, in new_func
    return f(get_current_context(), *args, **kwargs)
  File "/home/aubrey/.local/lib/python3.8/site-packages/papermill/cli.py", line 250, in papermill
    execute_notebook(
  File "/home/aubrey/.local/lib/python3.8/site-packages/papermill/execute.py", line 122, in execute_notebook
    raise_for_execution_errors(nb, output_path)
  File "/home/aubrey/.local/lib/python3.8/site-packages/papermill/execute.py", line 234, in raise_for_execution_errors
    raise error
papermill.exceptions.PapermillExecutionError: 
---------------------------------------------------------------------------
Exception encountered at "In [12]":
---------------------------------------------------------------------------
AssertionError                            Traceback (most recent call last)
<timed exec> in <module>

<timed exec> in validate_dwca(uuid)

AssertionError: wget -O FFF07216FFA41642FFBAFFE7FFCA482A.zip http://tb.plazi.org/GgServer/dwca/FFF07216FFA41642FFBAFFE7FFCA482A.zip failed

